new Promise(function(resolve, reject) {
    setTimeout(() => {
      throw new Error("Whoops!");
    }, 1000);
  }).catch(console.log);

  //Не выполнится.здесь присутствует "скрытый try..catch" вокруг кода функции. 
  //Поэтому обрабатываются все синхронные ошибки. В этой 
  //ошибка генерируется не по ходу выполнения кода, а позже. 
  //Поэтому промис не может обработать её.